Traceback (most recent call last):
  File "/home/gedgar/knowledge_base_assembly/python_programs_and_containers/stand_alone_programs/modules/knowledge_base_load/run_kb_config_scripts.py", line 29, in run_kb_config_scripts
    result = subprocess.run(
             ^^^^^^^^^^^^^^^
  File "/usr/lib/python3.12/subprocess.py", line 571, in run
    raise CalledProcessError(retcode, process.args,
subprocess.CalledProcessError: Command '['/home/gedgar/postgres_env/bin/python3', '/home/gedgar/mount_kb_definitions/start.py']' returned non-zero exit status 1.

During handling of the above exception, another exception occurred:

Traceback (most recent call last):
  File "/home/gedgar/knowledge_base_assembly/python_programs_and_containers/stand_alone_programs/modules/knowledge_base_load/cold_start.py", line 85, in <module>
    main()
  File "/home/gedgar/knowledge_base_assembly/python_programs_and_containers/stand_alone_programs/modules/knowledge_base_load/cold_start.py", line 75, in main
    run_kb_config_scripts(update_dir, 15)
  File "/home/gedgar/knowledge_base_assembly/python_programs_and_containers/stand_alone_programs/modules/knowledge_base_load/run_kb_config_scripts.py", line 56, in run_kb_config_scripts
    raise RuntimeError(f"Start script execution failed with exit code {e.returncode}: {e.stderr}")
RuntimeError: Start script execution failed with exit code 1: Traceback (most recent call last):
  File "/home/gedgar/mount_kb_definitions/start.py", line 136, in <module>
    raise RuntimeError("kb not built")
RuntimeError: kb not built

